<?xml version="1.0" encoding="UTF-8"?>
<!-- Generated by org.testng.reporters.JUnitXMLReporter -->
<testsuite ignored="0" hostname="LAPTOP-GLPUBTPG" failures="2" tests="8" name="Testcases" time="0.076" errors="0" timestamp="2025-08-13T18:06:47 IST">
  <testcase classname="seleniumInterviewProgram.Part17_01_HandlingFailedTestCases" name="testcase1" time="0.017">
    <skipped/>
  </testcase> <!-- testcase1 -->
  <testcase classname="seleniumInterviewProgram.Part17_01_HandlingFailedTestCases" name="testcase2" time="0.017">
    <skipped/>
  </testcase> <!-- testcase2 -->
  <testcase classname="seleniumInterviewProgram.Part17_01_HandlingFailedTestCases" name="testcase1" time="0.001">
    <skipped/>
  </testcase> <!-- testcase1 -->
  <testcase classname="seleniumInterviewProgram.Part17_01_HandlingFailedTestCases" name="testcase2" time="0.002">
    <skipped/>
  </testcase> <!-- testcase2 -->
  <testcase classname="seleniumInterviewProgram.Part17_01_HandlingFailedTestCases" name="testcase1" time="0.001">
    <skipped/>
  </testcase> <!-- testcase1 -->
  <testcase classname="seleniumInterviewProgram.Part17_01_HandlingFailedTestCases" name="testcase2" time="0.001">
    <skipped/>
  </testcase> <!-- testcase2 -->
  <testcase classname="seleniumInterviewProgram.Part17_01_HandlingFailedTestCases" name="testcase1" time="0.001">
    <failure type="java.lang.AssertionError" message="expected [false] but found [true]">
      <![CDATA[java.lang.AssertionError: expected [false] but found [true]
at org.testng.Assert.fail(Assert.java:111)
at org.testng.Assert.failNotEquals(Assert.java:1590)
at org.testng.Assert.assertEqualsImpl(Assert.java:150)
at org.testng.Assert.assertEquals(Assert.java:132)
at org.testng.Assert.assertEquals(Assert.java:1079)
at org.testng.Assert.assertEquals(Assert.java:1043)
at org.testng.Assert.assertEquals(Assert.java:1089)
at seleniumInterviewProgram.Part17_01_HandlingFailedTestCases.testcase1(Part17_01_HandlingFailedTestCases.java:15)
at java.base/jdk.internal.reflect.DirectMethodHandleAccessor.invoke(DirectMethodHandleAccessor.java:103)
at java.base/java.lang.reflect.Method.invoke(Method.java:580)
at org.testng.internal.invokers.MethodInvocationHelper.invokeMethod(MethodInvocationHelper.java:141)
at org.testng.internal.invokers.TestInvoker.invokeMethod(TestInvoker.java:687)
at org.testng.internal.invokers.TestInvoker.retryFailed(TestInvoker.java:269)
at org.testng.internal.invokers.MethodRunner.runInSequence(MethodRunner.java:76)
at org.testng.internal.invokers.TestInvoker$MethodInvocationAgent.invoke(TestInvoker.java:995)
at org.testng.internal.invokers.TestInvoker.invokeTestMethods(TestInvoker.java:203)
at org.testng.internal.invokers.TestMethodWorker.invokeTestMethods(TestMethodWorker.java:154)
at org.testng.internal.invokers.TestMethodWorker.run(TestMethodWorker.java:134)
at java.base/java.util.concurrent.Executors$RunnableAdapter.call(Executors.java:572)
at java.base/java.util.concurrent.FutureTask.run(FutureTask.java:317)
at org.testng.internal.thread.graph.TestNGFutureTask.run(TestNGFutureTask.java:22)
at java.base/java.util.concurrent.ThreadPoolExecutor.runWorker(ThreadPoolExecutor.java:1144)
at java.base/java.util.concurrent.ThreadPoolExecutor$Worker.run(ThreadPoolExecutor.java:642)
at java.base/java.lang.Thread.run(Thread.java:1575)
]]>
    </failure>
  </testcase> <!-- testcase1 -->
  <testcase classname="seleniumInterviewProgram.Part17_01_HandlingFailedTestCases" name="testcase2" time="0.001">
    <failure type="java.lang.AssertionError" message="expected [false] but found [true]">
      <![CDATA[java.lang.AssertionError: expected [false] but found [true]
at org.testng.Assert.fail(Assert.java:111)
at org.testng.Assert.failNotEquals(Assert.java:1590)
at org.testng.Assert.assertEqualsImpl(Assert.java:150)
at org.testng.Assert.assertEquals(Assert.java:132)
at org.testng.Assert.assertEquals(Assert.java:1079)
at org.testng.Assert.assertEquals(Assert.java:1043)
at org.testng.Assert.assertEquals(Assert.java:1089)
at seleniumInterviewProgram.Part17_01_HandlingFailedTestCases.testcase2(Part17_01_HandlingFailedTestCases.java:21)
at java.base/jdk.internal.reflect.DirectMethodHandleAccessor.invoke(DirectMethodHandleAccessor.java:103)
at java.base/java.lang.reflect.Method.invoke(Method.java:580)
at org.testng.internal.invokers.MethodInvocationHelper.invokeMethod(MethodInvocationHelper.java:141)
at org.testng.internal.invokers.TestInvoker.invokeMethod(TestInvoker.java:687)
at org.testng.internal.invokers.TestInvoker.retryFailed(TestInvoker.java:269)
at org.testng.internal.invokers.MethodRunner.runInSequence(MethodRunner.java:76)
at org.testng.internal.invokers.TestInvoker$MethodInvocationAgent.invoke(TestInvoker.java:995)
at org.testng.internal.invokers.TestInvoker.invokeTestMethods(TestInvoker.java:203)
at org.testng.internal.invokers.TestMethodWorker.invokeTestMethods(TestMethodWorker.java:154)
at org.testng.internal.invokers.TestMethodWorker.run(TestMethodWorker.java:134)
at java.base/java.util.concurrent.Executors$RunnableAdapter.call(Executors.java:572)
at java.base/java.util.concurrent.FutureTask.run(FutureTask.java:317)
at org.testng.internal.thread.graph.TestNGFutureTask.run(TestNGFutureTask.java:22)
at java.base/java.util.concurrent.ThreadPoolExecutor.runWorker(ThreadPoolExecutor.java:1144)
at java.base/java.util.concurrent.ThreadPoolExecutor$Worker.run(ThreadPoolExecutor.java:642)
at java.base/java.lang.Thread.run(Thread.java:1575)
]]>
    </failure>
  </testcase> <!-- testcase2 -->
</testsuite> <!-- Testcases -->
